2024-01-12 22:24:20.221741: I tensorflow/core/util/port.cc:113] oneDNN custom operations are on. You may see slightly different numerical results due to floating-point round-off errors from different computation orders. To turn them off, set the environment variable `TF_ENABLE_ONEDNN_OPTS=0`.
2024-01-12 22:24:20.243685: E external/local_xla/xla/stream_executor/cuda/cuda_dnn.cc:9261] Unable to register cuDNN factory: Attempting to register factory for plugin cuDNN when one has already been registered
2024-01-12 22:24:20.243704: E external/local_xla/xla/stream_executor/cuda/cuda_fft.cc:607] Unable to register cuFFT factory: Attempting to register factory for plugin cuFFT when one has already been registered
2024-01-12 22:24:20.244250: E external/local_xla/xla/stream_executor/cuda/cuda_blas.cc:1515] Unable to register cuBLAS factory: Attempting to register factory for plugin cuBLAS when one has already been registered
2024-01-12 22:24:20.247799: I tensorflow/core/platform/cpu_feature_guard.cc:182] This TensorFlow binary is optimized to use available CPU instructions in performance-critical operations.
To enable the following instructions: AVX2 AVX512F AVX512_VNNI FMA, in other operations, rebuild TensorFlow with the appropriate compiler flags.
2024-01-12 22:24:20.681075: W tensorflow/compiler/tf2tensorrt/utils/py_utils.cc:38] TF-TRT Warning: Could not find TensorRT
2024-01-12 22:24:20.983181: I external/local_xla/xla/stream_executor/cuda/cuda_executor.cc:901] successful NUMA node read from SysFS had negative value (-1), but there must be at least one NUMA node, so returning NUMA node zero. See more at https://github.com/torvalds/linux/blob/v6.0/Documentation/ABI/testing/sysfs-bus-pci#L344-L355
2024-01-12 22:24:21.013098: I external/local_xla/xla/stream_executor/cuda/cuda_executor.cc:901] successful NUMA node read from SysFS had negative value (-1), but there must be at least one NUMA node, so returning NUMA node zero. See more at https://github.com/torvalds/linux/blob/v6.0/Documentation/ABI/testing/sysfs-bus-pci#L344-L355
2024-01-12 22:24:21.013230: I external/local_xla/xla/stream_executor/cuda/cuda_executor.cc:901] successful NUMA node read from SysFS had negative value (-1), but there must be at least one NUMA node, so returning NUMA node zero. See more at https://github.com/torvalds/linux/blob/v6.0/Documentation/ABI/testing/sysfs-bus-pci#L344-L355
2024-01-12 22:24:21.014191: I external/local_xla/xla/stream_executor/cuda/cuda_executor.cc:901] successful NUMA node read from SysFS had negative value (-1), but there must be at least one NUMA node, so returning NUMA node zero. See more at https://github.com/torvalds/linux/blob/v6.0/Documentation/ABI/testing/sysfs-bus-pci#L344-L355
2024-01-12 22:24:21.014373: I external/local_xla/xla/stream_executor/cuda/cuda_executor.cc:901] successful NUMA node read from SysFS had negative value (-1), but there must be at least one NUMA node, so returning NUMA node zero. See more at https://github.com/torvalds/linux/blob/v6.0/Documentation/ABI/testing/sysfs-bus-pci#L344-L355
2024-01-12 22:24:21.014574: I external/local_xla/xla/stream_executor/cuda/cuda_executor.cc:901] successful NUMA node read from SysFS had negative value (-1), but there must be at least one NUMA node, so returning NUMA node zero. See more at https://github.com/torvalds/linux/blob/v6.0/Documentation/ABI/testing/sysfs-bus-pci#L344-L355
2024-01-12 22:24:21.791632: I external/local_xla/xla/stream_executor/cuda/cuda_executor.cc:901] successful NUMA node read from SysFS had negative value (-1), but there must be at least one NUMA node, so returning NUMA node zero. See more at https://github.com/torvalds/linux/blob/v6.0/Documentation/ABI/testing/sysfs-bus-pci#L344-L355
2024-01-12 22:24:21.791800: I external/local_xla/xla/stream_executor/cuda/cuda_executor.cc:901] successful NUMA node read from SysFS had negative value (-1), but there must be at least one NUMA node, so returning NUMA node zero. See more at https://github.com/torvalds/linux/blob/v6.0/Documentation/ABI/testing/sysfs-bus-pci#L344-L355
2024-01-12 22:24:21.791937: I external/local_xla/xla/stream_executor/cuda/cuda_executor.cc:901] successful NUMA node read from SysFS had negative value (-1), but there must be at least one NUMA node, so returning NUMA node zero. See more at https://github.com/torvalds/linux/blob/v6.0/Documentation/ABI/testing/sysfs-bus-pci#L344-L355
2024-01-12 22:24:21.792016: I tensorflow/core/common_runtime/gpu/gpu_device.cc:1929] Created device /job:localhost/replica:0/task:0/device:GPU:0 with 4432 MB memory:  -> device: 0, name: NVIDIA GeForce GTX 1660 SUPER, pci bus id: 0000:02:00.0, compute capability: 7.5
2024-01-12 22:24:23.949134: I external/local_xla/xla/stream_executor/cuda/cuda_dnn.cc:454] Loaded cuDNN version 8904
2024-01-12 22:24:24.890392: I external/local_xla/xla/service/service.cc:168] XLA service 0x7f4ae273e770 initialized for platform CUDA (this does not guarantee that XLA will be used). Devices:
2024-01-12 22:24:24.890407: I external/local_xla/xla/service/service.cc:176]   StreamExecutor device (0): NVIDIA GeForce GTX 1660 SUPER, Compute Capability 7.5
2024-01-12 22:24:24.893235: I tensorflow/compiler/mlir/tensorflow/utils/dump_mlir_util.cc:269] disabling MLIR crash reproducer, set env var `MLIR_CRASH_REPRODUCER_DIRECTORY` to enable.
WARNING: All log messages before absl::InitializeLog() is called are written to STDERR
I0000 00:00:1705116264.954875   14087 device_compiler.h:186] Compiled cluster using XLA!  This line is logged at most once for the lifetime of the process.
WARNING: Version mismatch detected: You are trying to connect to a simulator that might be incompatible with this API 
WARNING: Client API version     = 0.9.15 
WARNING: Simulator API version  = 0.9.14 
  0%|          | 0/9678 [00:00<?, ?episode/s]
Started episode 323 of 10000
Finished episode 323 of 10000
len(agent.replay_memory): 20045
Count of epochs trained: 0	Goal: 1

  0%|          | 0/1 [00:00<?, ?epoch/s][Acurrent_states.shape: (512, 128, 128, 3)	new_current_states.shape: (512, 128, 128, 3)
Error message: in user code:

    File "/home/nsambhu/anaconda3/envs/carla_py3.9/lib/python3.9/site-packages/keras/src/engine/training.py", line 2440, in predict_function  *
        return step_function(self, iterator)
    File "/home/nsambhu/anaconda3/envs/carla_py3.9/lib/python3.9/site-packages/keras/src/engine/training.py", line 2425, in step_function  **
        outputs = model.distribute_strategy.run(run_step, args=(data,))
    File "/home/nsambhu/anaconda3/envs/carla_py3.9/lib/python3.9/site-packages/keras/src/engine/training.py", line 2413, in run_step  **
        outputs = model.predict_step(data)
    File "/home/nsambhu/anaconda3/envs/carla_py3.9/lib/python3.9/site-packages/keras/src/engine/training.py", line 2381, in predict_step
        return self(x, training=False)
    File "/home/nsambhu/anaconda3/envs/carla_py3.9/lib/python3.9/site-packages/keras/src/utils/traceback_utils.py", line 70, in error_handler
        raise e.with_traceback(filtered_tb) from None
    File "/home/nsambhu/anaconda3/envs/carla_py3.9/lib/python3.9/site-packages/keras/src/engine/input_spec.py", line 298, in assert_input_compatibility
        raise ValueError(

    ValueError: Input 0 of layer "model" is incompatible with the layer: expected shape=(None, 4, 128, 128, 3), found shape=(1, 128, 128, 3)

  0%|          | 0/1 [00:00<?, ?epoch/s]
  0%|          | 0/9678 [00:06<?, ?episode/s]
Error message: in user code:

    File "/home/nsambhu/anaconda3/envs/carla_py3.9/lib/python3.9/site-packages/keras/src/engine/training.py", line 2440, in predict_function  *
        return step_function(self, iterator)
    File "/home/nsambhu/anaconda3/envs/carla_py3.9/lib/python3.9/site-packages/keras/src/engine/training.py", line 2425, in step_function  **
        outputs = model.distribute_strategy.run(run_step, args=(data,))
    File "/home/nsambhu/anaconda3/envs/carla_py3.9/lib/python3.9/site-packages/keras/src/engine/training.py", line 2413, in run_step  **
        outputs = model.predict_step(data)
    File "/home/nsambhu/anaconda3/envs/carla_py3.9/lib/python3.9/site-packages/keras/src/engine/training.py", line 2381, in predict_step
        return self(x, training=False)
    File "/home/nsambhu/anaconda3/envs/carla_py3.9/lib/python3.9/site-packages/keras/src/utils/traceback_utils.py", line 70, in error_handler
        raise e.with_traceback(filtered_tb) from None
    File "/home/nsambhu/anaconda3/envs/carla_py3.9/lib/python3.9/site-packages/keras/src/engine/input_spec.py", line 298, in assert_input_compatibility
        raise ValueError(

    ValueError: Input 0 of layer "model_1" is incompatible with the layer: expected shape=(None, 4, 128, 128, 3), found shape=(1, 128, 128, 3)

Traceback (most recent call last):
  File "/home/nsambhu/github/carla-race/run/2023_12_18_16rl_custom2.py", line 721, in <module>
    agent.train()
  File "/home/nsambhu/github/carla-race/run/2023_12_18_16rl_custom2.py", line 416, in train
    future_qs_list = self.target_model.predict(new_current_states, PREDICTION_BATCH_SIZE, verbose=0)
  File "/home/nsambhu/anaconda3/envs/carla_py3.9/lib/python3.9/site-packages/keras/src/utils/traceback_utils.py", line 70, in error_handler
    raise e.with_traceback(filtered_tb) from None
  File "/tmp/__autograph_generated_file5ksn235_.py", line 15, in tf__predict_function
    retval_ = ag__.converted_call(ag__.ld(step_function), (ag__.ld(self), ag__.ld(iterator)), None, fscope)
ValueError: in user code:

    File "/home/nsambhu/anaconda3/envs/carla_py3.9/lib/python3.9/site-packages/keras/src/engine/training.py", line 2440, in predict_function  *
        return step_function(self, iterator)
    File "/home/nsambhu/anaconda3/envs/carla_py3.9/lib/python3.9/site-packages/keras/src/engine/training.py", line 2425, in step_function  **
        outputs = model.distribute_strategy.run(run_step, args=(data,))
    File "/home/nsambhu/anaconda3/envs/carla_py3.9/lib/python3.9/site-packages/keras/src/engine/training.py", line 2413, in run_step  **
        outputs = model.predict_step(data)
    File "/home/nsambhu/anaconda3/envs/carla_py3.9/lib/python3.9/site-packages/keras/src/engine/training.py", line 2381, in predict_step
        return self(x, training=False)
    File "/home/nsambhu/anaconda3/envs/carla_py3.9/lib/python3.9/site-packages/keras/src/utils/traceback_utils.py", line 70, in error_handler
        raise e.with_traceback(filtered_tb) from None
    File "/home/nsambhu/anaconda3/envs/carla_py3.9/lib/python3.9/site-packages/keras/src/engine/input_spec.py", line 298, in assert_input_compatibility
        raise ValueError(

    ValueError: Input 0 of layer "model_1" is incompatible with the layer: expected shape=(None, 4, 128, 128, 3), found shape=(1, 128, 128, 3)

Error during episode 323
