Start run at count 1
CarlaUE4-Linux: no process found
4.26.2-0+++UE4+Release-4.26 522 0
Disabling core dumps.
2024-01-13 01:28:12.199258: I tensorflow/core/util/port.cc:113] oneDNN custom operations are on. You may see slightly different numerical results due to floating-point round-off errors from different computation orders. To turn them off, set the environment variable `TF_ENABLE_ONEDNN_OPTS=0`.
2024-01-13 01:28:12.221110: E external/local_xla/xla/stream_executor/cuda/cuda_dnn.cc:9261] Unable to register cuDNN factory: Attempting to register factory for plugin cuDNN when one has already been registered
2024-01-13 01:28:12.221127: E external/local_xla/xla/stream_executor/cuda/cuda_fft.cc:607] Unable to register cuFFT factory: Attempting to register factory for plugin cuFFT when one has already been registered
2024-01-13 01:28:12.221744: E external/local_xla/xla/stream_executor/cuda/cuda_blas.cc:1515] Unable to register cuBLAS factory: Attempting to register factory for plugin cuBLAS when one has already been registered
2024-01-13 01:28:12.225135: I tensorflow/core/platform/cpu_feature_guard.cc:182] This TensorFlow binary is optimized to use available CPU instructions in performance-critical operations.
To enable the following instructions: AVX2 AVX512F AVX512_VNNI FMA, in other operations, rebuild TensorFlow with the appropriate compiler flags.
2024-01-13 01:28:12.649924: W tensorflow/compiler/tf2tensorrt/utils/py_utils.cc:38] TF-TRT Warning: Could not find TensorRT
2024-01-13 01:28:12.952730: I external/local_xla/xla/stream_executor/cuda/cuda_executor.cc:901] successful NUMA node read from SysFS had negative value (-1), but there must be at least one NUMA node, so returning NUMA node zero. See more at https://github.com/torvalds/linux/blob/v6.0/Documentation/ABI/testing/sysfs-bus-pci#L344-L355
2024-01-13 01:28:12.981418: I external/local_xla/xla/stream_executor/cuda/cuda_executor.cc:901] successful NUMA node read from SysFS had negative value (-1), but there must be at least one NUMA node, so returning NUMA node zero. See more at https://github.com/torvalds/linux/blob/v6.0/Documentation/ABI/testing/sysfs-bus-pci#L344-L355
2024-01-13 01:28:12.981705: I external/local_xla/xla/stream_executor/cuda/cuda_executor.cc:901] successful NUMA node read from SysFS had negative value (-1), but there must be at least one NUMA node, so returning NUMA node zero. See more at https://github.com/torvalds/linux/blob/v6.0/Documentation/ABI/testing/sysfs-bus-pci#L344-L355
2024-01-13 01:28:12.982438: I external/local_xla/xla/stream_executor/cuda/cuda_executor.cc:901] successful NUMA node read from SysFS had negative value (-1), but there must be at least one NUMA node, so returning NUMA node zero. See more at https://github.com/torvalds/linux/blob/v6.0/Documentation/ABI/testing/sysfs-bus-pci#L344-L355
2024-01-13 01:28:12.982567: I external/local_xla/xla/stream_executor/cuda/cuda_executor.cc:901] successful NUMA node read from SysFS had negative value (-1), but there must be at least one NUMA node, so returning NUMA node zero. See more at https://github.com/torvalds/linux/blob/v6.0/Documentation/ABI/testing/sysfs-bus-pci#L344-L355
2024-01-13 01:28:12.982667: I external/local_xla/xla/stream_executor/cuda/cuda_executor.cc:901] successful NUMA node read from SysFS had negative value (-1), but there must be at least one NUMA node, so returning NUMA node zero. See more at https://github.com/torvalds/linux/blob/v6.0/Documentation/ABI/testing/sysfs-bus-pci#L344-L355
2024-01-13 01:28:13.810969: I external/local_xla/xla/stream_executor/cuda/cuda_executor.cc:901] successful NUMA node read from SysFS had negative value (-1), but there must be at least one NUMA node, so returning NUMA node zero. See more at https://github.com/torvalds/linux/blob/v6.0/Documentation/ABI/testing/sysfs-bus-pci#L344-L355
2024-01-13 01:28:13.811095: I external/local_xla/xla/stream_executor/cuda/cuda_executor.cc:901] successful NUMA node read from SysFS had negative value (-1), but there must be at least one NUMA node, so returning NUMA node zero. See more at https://github.com/torvalds/linux/blob/v6.0/Documentation/ABI/testing/sysfs-bus-pci#L344-L355
2024-01-13 01:28:13.811206: I external/local_xla/xla/stream_executor/cuda/cuda_executor.cc:901] successful NUMA node read from SysFS had negative value (-1), but there must be at least one NUMA node, so returning NUMA node zero. See more at https://github.com/torvalds/linux/blob/v6.0/Documentation/ABI/testing/sysfs-bus-pci#L344-L355
2024-01-13 01:28:13.811299: I tensorflow/core/common_runtime/gpu/gpu_device.cc:1929] Created device /job:localhost/replica:0/task:0/device:GPU:0 with 4432 MB memory:  -> device: 0, name: NVIDIA GeForce GTX 1660 SUPER, pci bus id: 0000:02:00.0, compute capability: 7.5
2024-01-13 01:28:15.836064: I external/local_xla/xla/stream_executor/cuda/cuda_dnn.cc:454] Loaded cuDNN version 8904
2024-01-13 01:28:16.769702: I external/local_xla/xla/service/service.cc:168] XLA service 0x7f558e4c6cb0 initialized for platform CUDA (this does not guarantee that XLA will be used). Devices:
2024-01-13 01:28:16.769717: I external/local_xla/xla/service/service.cc:176]   StreamExecutor device (0): NVIDIA GeForce GTX 1660 SUPER, Compute Capability 7.5
2024-01-13 01:28:16.772481: I tensorflow/compiler/mlir/tensorflow/utils/dump_mlir_util.cc:269] disabling MLIR crash reproducer, set env var `MLIR_CRASH_REPRODUCER_DIRECTORY` to enable.
WARNING: All log messages before absl::InitializeLog() is called are written to STDERR
I0000 00:00:1705127296.833355  401342 device_compiler.h:186] Compiled cluster using XLA!  This line is logged at most once for the lifetime of the process.
WARNING: Version mismatch detected: You are trying to connect to a simulator that might be incompatible with this API 
WARNING: Client API version     = 0.9.15 
WARNING: Simulator API version  = 0.9.14 
  0%|          | 0/9638 [00:00<?, ?episode/s]
Started episode 363 of 10000
Finished initializing all actions. Predicting from model.
(128, 128, 3)
(128, 128, 3)
  0%|          | 0/9638 [00:00<?, ?episode/s]
Error message: in user code:

    File "/home/nsambhu/anaconda3/envs/carla_py3.9/lib/python3.9/site-packages/keras/src/engine/training.py", line 2440, in predict_function  *
        return step_function(self, iterator)
    File "/home/nsambhu/anaconda3/envs/carla_py3.9/lib/python3.9/site-packages/keras/src/engine/training.py", line 2425, in step_function  **
        outputs = model.distribute_strategy.run(run_step, args=(data,))
    File "/home/nsambhu/anaconda3/envs/carla_py3.9/lib/python3.9/site-packages/keras/src/engine/training.py", line 2413, in run_step  **
        outputs = model.predict_step(data)
    File "/home/nsambhu/anaconda3/envs/carla_py3.9/lib/python3.9/site-packages/keras/src/engine/training.py", line 2381, in predict_step
        return self(x, training=False)
    File "/home/nsambhu/anaconda3/envs/carla_py3.9/lib/python3.9/site-packages/keras/src/utils/traceback_utils.py", line 70, in error_handler
        raise e.with_traceback(filtered_tb) from None
    File "/home/nsambhu/anaconda3/envs/carla_py3.9/lib/python3.9/site-packages/keras/src/engine/input_spec.py", line 298, in assert_input_compatibility
        raise ValueError(

    ValueError: Input 0 of layer "model" is incompatible with the layer: expected shape=(None, 4, 128, 128, 3), found shape=(None, 128, 128, 3)

Traceback (most recent call last):
  File "/home/nsambhu/github/carla-race/run/2023_12_18_16rl_custom2.py", line 669, in <module>
    action = np.argmax(agent.get_qs(current_state))
  File "/home/nsambhu/github/carla-race/run/2023_12_18_16rl_custom2.py", line 490, in get_qs
    return self.model.predict(np.expand_dims(state, axis=0), verbose=0)[0]
  File "/home/nsambhu/anaconda3/envs/carla_py3.9/lib/python3.9/site-packages/keras/src/utils/traceback_utils.py", line 70, in error_handler
    raise e.with_traceback(filtered_tb) from None
  File "/tmp/__autograph_generated_file3k4a99zh.py", line 15, in tf__predict_function
    retval_ = ag__.converted_call(ag__.ld(step_function), (ag__.ld(self), ag__.ld(iterator)), None, fscope)
ValueError: in user code:

    File "/home/nsambhu/anaconda3/envs/carla_py3.9/lib/python3.9/site-packages/keras/src/engine/training.py", line 2440, in predict_function  *
        return step_function(self, iterator)
    File "/home/nsambhu/anaconda3/envs/carla_py3.9/lib/python3.9/site-packages/keras/src/engine/training.py", line 2425, in step_function  **
        outputs = model.distribute_strategy.run(run_step, args=(data,))
    File "/home/nsambhu/anaconda3/envs/carla_py3.9/lib/python3.9/site-packages/keras/src/engine/training.py", line 2413, in run_step  **
        outputs = model.predict_step(data)
    File "/home/nsambhu/anaconda3/envs/carla_py3.9/lib/python3.9/site-packages/keras/src/engine/training.py", line 2381, in predict_step
        return self(x, training=False)
    File "/home/nsambhu/anaconda3/envs/carla_py3.9/lib/python3.9/site-packages/keras/src/utils/traceback_utils.py", line 70, in error_handler
        raise e.with_traceback(filtered_tb) from None
    File "/home/nsambhu/anaconda3/envs/carla_py3.9/lib/python3.9/site-packages/keras/src/engine/input_spec.py", line 298, in assert_input_compatibility
        raise ValueError(

    ValueError: Input 0 of layer "model" is incompatible with the layer: expected shape=(None, 4, 128, 128, 3), found shape=(None, 128, 128, 3)

Error during episode 363
(Allegedly) no exception occurred for run at count 1. CARLA Simulator may have crashed.
End run at count 1
Elapsed time: 00:00:43
done
